Workbook

Sheet Dashboard
B2: MOVIE BOX OFFICE ANALYTICS DASHBOARD
B3: 222 titles | 2000 - 2024 | Source: Cleaned Data table | Use the filter buttons on the Cleaned Data sheet (Genre / Release Year / Language) to slice the underlying dataset
B5: TOTAL MOVIES | G5: TOTAL REVENUE | L5: AVG IMDB RATING | Q5: AVG RUNTIME (MIN) | V5: NUMBER OF GENRES
B7: =COUNTA('Cleaned Data'!$B$5:$B$226) -> 222 | G7: =SUM('Cleaned Data'!$G$5:$G$226) -> 35425484000 | L7: =AVERAGE('Cleaned Data'!$H$5:$H$226) -> 6.5693694 | Q7: =AVERAGE('Cleaned Data'!$I$5:$I$226) -> 112.75676 | V7: =COUNTA('Pivot Tables'!$F$3:$F$14) -> 12

Sheet Pivot Tables
A1: 1) REVENUE BY RELEASE YEAR | F1: 2) GENRE DISTRIBUTION | K1: 3) LANGUAGE DISTRIBUTION | O1: (helper) All Directors
A2: Release Year | B2: Total Revenue | C2: Movie Count | D2: Avg IMDb Rating | F2: Genre | G2: Movie Count | H2: Total Revenue | I2: % of Total | K2: Language | L2: Movie Count | M2: % of Total | O2: Director | P2: Total Revenue | Q2: Movie Count | R2: Tiebreak Key
A3: 2000 | B3: =SUMIFS('Cleaned Data'!$G$5:$G$226,'Cleaned Data'!$E$5:$E$226,A3) -> 1765383000 | C3: =COUNTIFS('Cleaned Data'!$E$5:$E$226,A3) -> 10 | D3: =AVERAGEIFS('Cleaned Data'!$H$5:$H$226,'Cleaned Data'!$E$5:$E$226,A3) -> 6.79 | F3: Action | G3: =COUNTIFS('Cleaned Data'!$C$5:$C$226,F3) -> 16 | H3: =SUMIFS('Cleaned Data'!$G$5:$G$226,'Cleaned Data'!$C$5:$C$226,F3) -> 4927039000 | I3: =G3/COUNTA('Cleaned Data'!$C$5:$C$226) -> 0.072072072 | K3: English | L3: =COUNTIFS('Cleaned Data'!$J$5:$J$226,K3) -> 13 | M3: =L3/COUNTA('Cleaned Data'!$J$5:$J$226) -> 0.058558559 | O3: Aisha Bello | P3: =SUMIFS('Cleaned Data'!$G$5:$G$226,'Cleaned Data'!$D$5:$D$226,O3) -> 32074000 | Q3: =COUNTIFS('Cleaned Data'!$D$5:$D$226,O3) -> 1 | R3: =P3+ROW()/10000000 -> 32074000
A4: 2001 | B4: =SUMIFS('Cleaned Data'!$G$5:$G$226,'Cleaned Data'!$E$5:$E$226,A4) -> 280442000 | C4: =COUNTIFS('Cleaned Data'!$E$5:$E$226,A4) -> 4 | D4: =AVERAGEIFS('Cleaned Data'!$H$5:$H$226,'Cleaned Data'!$E$5:$E$226,A4) -> 6.75 | F4: Adventure | G4: =COUNTIFS('Cleaned Data'!$C$5:$C$226,F4) -> 15 | H4: =SUMIFS('Cleaned Data'!$G$5:$G$226,'Cleaned Data'!$C$5:$C$226,F4) -> 3075929000 | I4: =G4/COUNTA('Cleaned Data'!$C$5:$C$226) -> 0.067567568 | K4: French | L4: =COUNTIFS('Cleaned Data'!$J$5:$J$226,K4) -> 24 | M4: =L4/COUNTA('Cleaned Data'!$J$5:$J$226) -> 0.10810811 | O4: Amara Johnson | P4: =SUMIFS('Cleaned Data'!$G$5:$G$226,'Cleaned Data'!$D$5:$D$226,O4) -> 2062082000 | Q4: =COUNTIFS('Cleaned Data'!$D$5:$D$226,O4) -> 7 | R4: =P4+ROW()/10000000 -> 2062082000
A5: 2002 | B5: =SUMIFS('Cleaned Data'!$G$5:$G$226,'Cleaned Data'!$E$5:$E$226,A5) -> 3310716500 | C5: =COUNTIFS('Cleaned Data'!$E$5:$E$226,A5) -> 16 | D5: =AVERAGEIFS('Cleaned Data'!$H$5:$H$226,'Cleaned Data'!$E$5:$E$226,A5) -> 6.78125 | F5: Animation | G5: =COUNTIFS('Cleaned Data'!$C$5:$C$226,F5) -> 20 | H5: =SUMIFS('Cleaned Data'!$G$5:$G$226,'Cleaned Data'!$C$5:$C$226,F5) -> 4177813000 | I5: =G5/COUNTA('Cleaned Data'!$C$5:$C$226) -> 0.09009009 | K5: German | L5: =COUNTIFS('Cleaned Data'!$J$5:$J$226,K5) -> 30 | M5: =L5/COUNTA('Cleaned Data'!$J$5:$J$226) -> 0.13513514 | O5: Ben Okafor | P5: =SUMIFS('Cleaned Data'!$G$5:$G$226,'Cleaned Data'!$D$5:$D$226,O5) -> 1112908500 | Q5: =COUNTIFS('Cleaned Data'!$D$5:$D$226,O5) -> 10 | R5: =P5+ROW()/10000000 -> 1112908500
A6: 2003 | B6: =SUMIFS('Cleaned Data'!$G$5:$G$226,'Cleaned Data'!$E$5:$E$226,A6) -> 1206099000 | C6: =COUNTIFS('Cleaned Data'!$E$5:$E$226,A6) -> 9 | D6: =AVERAGEIFS('Cleaned Data'!$H$5:$H$226,'Cleaned Data'!$E$5:$E$226,A6) -> 5.8666667 | F6: Comedy | G6: =COUNTIFS('Cleaned Data'!$C$5:$C$226,F6) -> 11 | H6: =SUMIFS('Cleaned Data'!$G$5:$G$226,'Cleaned Data'!$C$5:$C$226,F6) -> 607203500 | I6: =G6/COUNTA('Cleaned Data'!$C$5:$C$226) -> 0.04954955 | K6: Hindi | L6: =COUNTIFS('Cleaned Data'!$J$5:$J$226,K6) -> 24 | M6: =L6/COUNTA('Cleaned Data'!$J$5:$J$226) -> 0.10810811 | O6: Clara Dubois | P6: =SUMIFS('Cleaned Data'!$G$5:$G$226,'Cleaned Data'!$D$5:$D$226,O6) -> 1941688000 | Q6: =COUNTIFS('Cleaned Data'!$D$5:$D$226,O6) -> 12 | R6: =P6+ROW()/10000000 -> 1941688000
A7: 2004 | B7: =SUMIFS('Cleaned Data'!$G$5:$G$226,'Cleaned Data'!$E$5:$E$226,A7) -> 2703789000 | C7: =COUNTIFS('Cleaned Data'!$E$5:$E$226,A7) -> 14 | D7: =AVERAGEIFS('Cleaned Data'!$H$5:$H$226,'Cleaned Data'!$E$5:$E$226,A7) -> 7.1571429 | F7: Crime | G7: =COUNTIFS('Cleaned Data'!$C$5:$C$226,F7) -> 19 | H7: =SUMIFS('Cleaned Data'!$G$5:$G$226,'Cleaned Data'!$C$5:$C$226,F7) -> 2231703500 | I7: =G7/COUNTA('Cleaned Data'!$C$5:$C$226) -> 0.085585586 | K7: Italian | L7: =COUNTIFS('Cleaned Data'!$J$5:$J$226,K7) -> 27 | M7: =L7/COUNTA('Cleaned Data'!$J$5:$J$226) -> 0.12162162 | O7: Connor Walsh | P7: =SUMIFS('Cleaned Data'!$G$5:$G$226,'Cleaned Data'!$D$5:$D$226,O7) -> 1280369000 | Q7: =COUNTIFS('Cleaned Data'!$D$5:$D$226,O7) -> 6 | R7: =P7+ROW()/10000000 -> 1280369000
A8: 2005 | B8: =SUMIFS('Cleaned Data'!$G$5:$G$226,'Cleaned Data'!$E$5:$E$226,A8) -> 667580000 | C8: =COUNTIFS('Cleaned Data'!$E$5:$E$226,A8) -> 10 | D8: =AVERAGEIFS('Cleaned Data'!$H$5:$H$226,'Cleaned Data'!$E$5:$E$226,A8) -> 6.64 | F8: Documentary | G8: =COUNTIFS('Cleaned Data'!$C$5:$C$226,F8) -> 23 | H8: =SUMIFS('Cleaned Data'!$G$5:$G$226,'Cleaned Data'!$C$5:$C$226,F8) -> 345296000 | I8: =G8/COUNTA('Cleaned Data'!$C$5:$C$226) -> 0.1036036 | K8: Japanese | L8: =COUNTIFS('Cleaned Data'!$J$5:$J$226,K8) -> 16 | M8: =L8/COUNTA('Cleaned Data'!$J$5:$J$226) -> 0.072072072 | O8: Daniel Ortiz | P8: =SUMIFS('Cleaned Data'!$G$5:$G$226,'Cleaned Data'!$D$5:$D$226,O8) -> 778541000 | Q8: =COUNTIFS('Cleaned Data'!$D$5:$D$226,O8) -> 3 | R8: =P8+ROW()/10000000 -> 7.78541e+08
A9: 2006 | B9: =SUMIFS('Cleaned Data'!$G$5:$G$226,'Cleaned Data'!$E$5:$E$226,A9) -> 825324500 | C9: =COUNTIFS('Cleaned Data'!$E$5:$E$226,A9) -> 7 | D9: =AVERAGEIFS('Cleaned Data'!$H$5:$H$226,'Cleaned Data'!$E$5:$E$226,A9) -> 6.6285714 | F9: Drama | G9: =COUNTIFS('Cleaned Data'!$C$5:$C$226,F9) -> 21 | H9: =SUMIFS('Cleaned Data'!$G$5:$G$226,'Cleaned Data'!$C$5:$C$226,F9) -> 1473572500 | I9: =G9/COUNTA('Cleaned Data'!$C$5:$C$226) -> 0.094594595 | K9: Korean | L9: =COUNTIFS('Cleaned Data'!$J$5:$J$226,K9) -> 19 | M9: =L9/COUNTA('Cleaned Data'!$J$5:$J$226) -> 0.085585586 | O9: David Chen | P9: =SUMIFS('Cleaned Data'!$G$5:$G$226,'Cleaned Data'!$D$5:$D$226,O9) -> 714540000 | Q9: =COUNTIFS('Cleaned Data'!$D$5:$D$226,O9) -> 7 | R9: =P9+ROW()/10000000 -> 7.1454e+08
A10: 2007 | B10: =SUMIFS('Cleaned Data'!$G$5:$G$226,'Cleaned Data'!$E$5:$E$226,A10) -> 753472000 | C10: =COUNTIFS('Cleaned Data'!$E$5:$E$226,A10) -> 9 | D10: =AVERAGEIFS('Cleaned Data'!$H$5:$H$226,'Cleaned Data'!$E$5:$E$226,A10) -> 5.9 | F10: Fantasy | G10: =COUNTIFS('Cleaned Data'!$C$5:$C$226,F10) -> 23 | H10: =SUMIFS('Cleaned Data'!$G$5:$G$226,'Cleaned Data'!$C$5:$C$226,F10) -> 7733727000 | I10: =G10/COUNTA('Cleaned Data'!$C$5:$C$226) -> 0.1036036 | K10: Mandarin | L10: =COUNTIFS('Cleaned Data'!$J$5:$J$226,K10) -> 25 | M10: =L10/COUNTA('Cleaned Data'!$J$5:$J$226) -> 0.11261261 | O10: Elena Voss | P10: =SUMIFS('Cleaned Data'!$G$5:$G$226,'Cleaned Data'!$D$5:$D$226,O10) -> 1169281000 | Q10: =COUNTIFS('Cleaned Data'!$D$5:$D$226,O10) -> 5 | R10: =P10+ROW()/10000000 -> 1169281000
A11: 2008 | B11: =SUMIFS('Cleaned Data'!$G$5:$G$226,'Cleaned Data'!$E$5:$E$226,A11) -> 2079789000 | C11: =COUNTIFS('Cleaned Data'!$E$5:$E$226,A11) -> 8 | D11: =AVERAGEIFS('Cleaned Data'!$H$5:$H$226,'Cleaned Data'!$E$5:$E$226,A11) -> 6.1375 | F11: Horror | G11: =COUNTIFS('Cleaned Data'!$C$5:$C$226,F11) -> 16 | H11: =SUMIFS('Cleaned Data'!$G$5:$G$226,'Cleaned Data'!$C$5:$C$226,F11) -> 1239274000 | I11: =G11/COUNTA('Cleaned Data'!$C$5:$C$226) -> 0.072072072 | K11: Portuguese | L11: =COUNTIFS('Cleaned Data'!$J$5:$J$226,K11) -> 24 | M11: =L11/COUNTA('Cleaned Data'!$J$5:$J$226) -> 0.10810811 | O11: Fatima Al-Sayed | P11: =SUMIFS('Cleaned Data'!$G$5:$G$226,'Cleaned Data'!$D$5:$D$226,O11) -> 544098000 | Q11: =COUNTIFS('Cleaned Data'!$D$5:$D$226,O11) -> 9 | R11: =P11+ROW()/10000000 -> 5.44098e+08
A12: 2009 | B12: =SUMIFS('Cleaned Data'!$G$5:$G$226,'Cleaned Data'!$E$5:$E$226,A12) -> 815554000 | C12: =COUNTIFS('Cleaned Data'!$E$5:$E$226,A12) -> 8 | D12: =AVERAGEIFS('Cleaned Data'!$H$5:$H$226,'Cleaned Data'!$E$5:$E$226,A12) -> 5.925 | F12: Romance | G12: =COUNTIFS('Cleaned Data'!$C$5:$C$226,F12) -> 17 | H12: =SUMIFS('Cleaned Data'!$G$5:$G$226,'Cleaned Data'!$C$5:$C$226,F12) -> 794524500 | I12: =G12/COUNTA('Cleaned Data'!$C$5:$C$226) -> 0.076576577 | K12: Spanish | L12: =COUNTIFS('Cleaned Data'!$J$5:$J$226,K12) -> 17 | M12: =L12/COUNTA('Cleaned Data'!$J$5:$J$226) -> 0.076576577 | O12: Grace Kim | P12: =SUMIFS('Cleaned Data'!$G$5:$G$226,'Cleaned Data'!$D$5:$D$226,O12) -> 2720814000 | Q12: =COUNTIFS('Cleaned Data'!$D$5:$D$226,O12) -> 7 | R12: =P12+ROW()/10000000 -> 2720814000
A13: 2010 | B13: =SUMIFS('Cleaned Data'!$G$5:$G$226,'Cleaned Data'!$E$5:$E$226,A13) -> 1367515000 | C13: =COUNTIFS('Cleaned Data'!$E$5:$E$226,A13) -> 9 | D13: =AVERAGEIFS('Cleaned Data'!$H$5:$H$226,'Cleaned Data'!$E$5:$E$226,A13) -> 6.8222222 | F13: Sci-Fi | G13: =COUNTIFS('Cleaned Data'!$C$5:$C$226,F13) -> 25 | H13: =SUMIFS('Cleaned Data'!$G$5:$G$226,'Cleaned Data'!$C$5:$C$226,F13) -> 7220232000 | I13: =G13/COUNTA('Cleaned Data'!$C$5:$C$226) -> 0.11261261 | K13: Unknown | L13: =COUNTIFS('Cleaned Data'!$J$5:$J$226,K13) -> 3 | M13: =L13/COUNTA('Cleaned Data'!$J$5:$J$226) -> 0.013513514 | O13: Hiroshi Tanaka | P13: =SUMIFS('Cleaned Data'!$G$5:$G$226,'Cleaned Data'!$D$5:$D$226,O13) -> 233428000 | Q13: =COUNTIFS('Cleaned Data'!$D$5:$D$226,O13) -> 6 | R13: =P13+ROW()/10000000 -> 2.33428e+08
A14: 2011 | B14: =SUMIFS('Cleaned Data'!$G$5:$G$226,'Cleaned Data'!$E$5:$E$226,A14) -> 709111000 | C14: =COUNTIFS('Cleaned Data'!$E$5:$E$226,A14) -> 11 | D14: =AVERAGEIFS('Cleaned Data'!$H$5:$H$226,'Cleaned Data'!$E$5:$E$226,A14) -> 6.2272727 | F14: Thriller | G14: =COUNTIFS('Cleaned Data'!$C$5:$C$226,F14) -> 16 | H14: =SUMIFS('Cleaned Data'!$G$5:$G$226,'Cleaned Data'!$C$5:$C$226,F14) -> 1599170000 | I14: =G14/COUNTA('Cleaned Data'!$C$5:$C$226) -> 0.072072072 | O14: Ingrid Solberg | P14: =SUMIFS('Cleaned Data'!$G$5:$G$226,'Cleaned Data'!$D$5:$D$226,O14) -> 1563723000 | Q14: =COUNTIFS('Cleaned Data'!$D$5:$D$226,O14) -> 12 | R14: =P14+ROW()/10000000 -> 1563723000
A15: 2012 | B15: =SUMIFS('Cleaned Data'!$G$5:$G$226,'Cleaned Data'!$E$5:$E$226,A15) -> 1555412000 | C15: =COUNTIFS('Cleaned Data'!$E$5:$E$226,A15) -> 8 | D15: =AVERAGEIFS('Cleaned Data'!$H$5:$H$226,'Cleaned Data'!$E$5:$E$226,A15) -> 6.8375 | O15: Isabella Rossi | P15: =SUMIFS('Cleaned Data'!$G$5:$G$226,'Cleaned Data'!$D$5:$D$226,O15) -> 2976056000 | Q15: =COUNTIFS('Cleaned Data'!$D$5:$D$226,O15) -> 12 | R15: =P15+ROW()/10000000 -> 2976056000
A16: 2013 | B16: =SUMIFS('Cleaned Data'!$G$5:$G$226,'Cleaned Data'!$E$5:$E$226,A16) -> 2691779000 | C16: =COUNTIFS('Cleaned Data'!$E$5:$E$226,A16) -> 11 | D16: =AVERAGEIFS('Cleaned Data'!$H$5:$H$226,'Cleaned Data'!$E$5:$E$226,A16) -> 6.4272727 | O16: James Whitfield | P16: =SUMIFS('Cleaned Data'!$G$5:$G$226,'Cleaned Data'!$D$5:$D$226,O16) -> 1514682000 | Q16: =COUNTIFS('Cleaned Data'!$D$5:$D$226,O16) -> 11 | R16: =P16+ROW()/10000000 -> 1514682000
A17: 2014 | B17: =SUMIFS('Cleaned Data'!$G$5:$G$226,'Cleaned Data'!$E$5:$E$226,A17) -> 829615500 | C17: =COUNTIFS('Cleaned Data'!$E$5:$E$226,A17) -> 9 | D17: =AVERAGEIFS('Cleaned Data'!$H$5:$H$226,'Cleaned Data'!$E$5:$E$226,A17) -> 6.4666667 | O17: Karim Haddad | P17: =SUMIFS('Cleaned Data'!$G$5:$G$226,'Cleaned Data'!$D$5:$D$226,O17) -> 1459923000 | Q17: =COUNTIFS('Cleaned Data'!$D$5:$D$226,O17) -> 8 | R17: =P17+ROW()/10000000 -> 1459923000
A18: 2015 | B18: =SUMIFS('Cleaned Data'!$G$5:$G$226,'Cleaned Data'!$E$5:$E$226,A18) -> 1325713000 | C18: =COUNTIFS('Cleaned Data'!$E$5:$E$226,A18) -> 4 | D18: =AVERAGEIFS('Cleaned Data'!$H$5:$H$226,'Cleaned Data'!$E$5:$E$226,A18) -> 5.575 | O18: Lucas Meyer | P18: =SUMIFS('Cleaned Data'!$G$5:$G$226,'Cleaned Data'!$D$5:$D$226,O18) -> 412489000 | Q18: =COUNTIFS('Cleaned Data'!$D$5:$D$226,O18) -> 5 | R18: =P18+ROW()/10000000 -> 4.12489e+08
A19: 2016 | B19: =SUMIFS('Cleaned Data'!$G$5:$G$226,'Cleaned Data'!$E$5:$E$226,A19) -> 1316185000 | C19: =COUNTIFS('Cleaned Data'!$E$5:$E$226,A19) -> 8 | D19: =AVERAGEIFS('Cleaned Data'!$H$5:$H$226,'Cleaned Data'!$E$5:$E$226,A19) -> 6.8625 | O19: Marco Bianchi | P19: =SUMIFS('Cleaned Data'!$G$5:$G$226,'Cleaned Data'!$D$5:$D$226,O19) -> 754702000 | Q19: =COUNTIFS('Cleaned Data'!$D$5:$D$226,O19) -> 5 | R19: =P19+ROW()/10000000 -> 7.54702e+08
A20: 2017 | B20: =SUMIFS('Cleaned Data'!$G$5:$G$226,'Cleaned Data'!$E$5:$E$226,A20) -> 631051000 | C20: =COUNTIFS('Cleaned Data'!$E$5:$E$226,A20) -> 7 | D20: =AVERAGEIFS('Cleaned Data'!$H$5:$H$226,'Cleaned Data'!$E$5:$E$226,A20) -> 7.2142857 | O20: Marcus Reyes | P20: =SUMIFS('Cleaned Data'!$G$5:$G$226,'Cleaned Data'!$D$5:$D$226,O20) -> 1590974000 | Q20: =COUNTIFS('Cleaned Data'!$D$5:$D$226,O20) -> 7 | R20: =P20+ROW()/10000000 -> 1590974000
A21: 2018 | B21: =SUMIFS('Cleaned Data'!$G$5:$G$226,'Cleaned Data'!$E$5:$E$226,A21) -> 1760846000 | C21: =COUNTIFS('Cleaned Data'!$E$5:$E$226,A21) -> 9 | D21: =AVERAGEIFS('Cleaned Data'!$H$5:$H$226,'Cleaned Data'!$E$5:$E$226,A21) -> 6.7111111 | O21: Mei Lin | P21: =SUMIFS('Cleaned Data'!$G$5:$G$226,'Cleaned Data'!$D$5:$D$226,O21) -> 968665000 | Q21: =COUNTIFS('Cleaned Data'!$D$5:$D$226,O21) -> 7 | R21: =P21+ROW()/10000000 -> 9.68665e+08
A22: 2019 | B22: =SUMIFS('Cleaned Data'!$G$5:$G$226,'Cleaned Data'!$E$5:$E$226,A22) -> 1419054000 | C22: =COUNTIFS('Cleaned Data'!$E$5:$E$226,A22) -> 10 | D22: =AVERAGEIFS('Cleaned Data'!$H$5:$H$226,'Cleaned Data'!$E$5:$E$226,A22) -> 6.65 | O22: Nadia Petrov | P22: =SUMIFS('Cleaned Data'!$G$5:$G$226,'Cleaned Data'!$D$5:$D$226,O22) -> 451138000 | Q22: =COUNTIFS('Cleaned Data'!$D$5:$D$226,O22) -> 7 | R22: =P22+ROW()/10000000 -> 4.51138e+08
A23: 2020 | B23: =SUMIFS('Cleaned Data'!$G$5:$G$226,'Cleaned Data'!$E$5:$E$226,A23) -> 4736750000 | C23: =COUNTIFS('Cleaned Data'!$E$5:$E$226,A23) -> 12 | D23: =AVERAGEIFS('Cleaned Data'!$H$5:$H$226,'Cleaned Data'!$E$5:$E$226,A23) -> 6.15 | O23: Olivia Bennett | P23: =SUMIFS('Cleaned Data'!$G$5:$G$226,'Cleaned Data'!$D$5:$D$226,O23) -> 2547597000 | Q23: =COUNTIFS('Cleaned Data'!$D$5:$D$226,O23) -> 14 | R23: =P23+ROW()/10000000 -> 2547597000
A24: 2021 | B24: =SUMIFS('Cleaned Data'!$G$5:$G$226,'Cleaned Data'!$E$5:$E$226,A24) -> 1085706000 | C24: =COUNTIFS('Cleaned Data'!$E$5:$E$226,A24) -> 11 | D24: =AVERAGEIFS('Cleaned Data'!$H$5:$H$226,'Cleaned Data'!$E$5:$E$226,A24) -> 7.2363636 | O24: Peter Novak | P24: =SUMIFS('Cleaned Data'!$G$5:$G$226,'Cleaned Data'!$D$5:$D$226,O24) -> 1117734000 | Q24: =COUNTIFS('Cleaned Data'!$D$5:$D$226,O24) -> 4 | R24: =P24+ROW()/10000000 -> 1117734000
A25: 2022 | B25: =SUMIFS('Cleaned Data'!$G$5:$G$226,'Cleaned Data'!$E$5:$E$226,A25) -> 751841500 | C25: =COUNTIFS('Cleaned Data'!$E$5:$E$226,A25) -> 7 | D25: =AVERAGEIFS('Cleaned Data'!$H$5:$H$226,'Cleaned Data'!$E$5:$E$226,A25) -> 6.5285714 | O25: Priya Nair | P25: =SUMIFS('Cleaned Data'!$G$5:$G$226,'Cleaned Data'!$D$5:$D$226,O25) -> 795730000 | Q25: =COUNTIFS('Cleaned Data'!$D$5:$D$226,O25) -> 7 | R25: =P25+ROW()/10000000 -> 7.9573e+08
A26: 2023 | B26: =SUMIFS('Cleaned Data'!$G$5:$G$226,'Cleaned Data'!$E$5:$E$226,A26) -> 408793000 | C26: =COUNTIFS('Cleaned Data'!$E$5:$E$226,A26) -> 5 | D26: =AVERAGEIFS('Cleaned Data'!$H$5:$H$226,'Cleaned Data'!$E$5:$E$226,A26) -> 7.06 | O26: Ryan Sullivan | P26: =SUMIFS('Cleaned Data'!$G$5:$G$226,'Cleaned Data'!$D$5:$D$226,O26) -> 164491500 | Q26: =COUNTIFS('Cleaned Data'!$D$5:$D$226,O26) -> 3 | R26: =P26+ROW()/10000000 -> 1.644915e+08
A27: 2024 | B27: =SUMIFS('Cleaned Data'!$G$5:$G$226,'Cleaned Data'!$E$5:$E$226,A27) -> 427963000 | C27: =COUNTIFS('Cleaned Data'!$E$5:$E$226,A27) -> 6 | D27: =AVERAGEIFS('Cleaned Data'!$H$5:$H$226,'Cleaned Data'!$E$5:$E$226,A27) -> 6.1833333 | O27: Sara Lindqvist | P27: =SUMIFS('Cleaned Data'!$G$5:$G$226,'Cleaned Data'!$D$5:$D$226,O27) -> 427617000 | Q27: =COUNTIFS('Cleaned Data'!$D$5:$D$226,O27) -> 5 | R27: =P27+ROW()/10000000 -> 4.27617e+08
O28: Sophie Laurent | P28: =SUMIFS('Cleaned Data'!$G$5:$G$226,'Cleaned Data'!$D$5:$D$226,O28) -> 1059556000 | Q28: =COUNTIFS('Cleaned Data'!$D$5:$D$226,O28) -> 6 | R28: =P28+ROW()/10000000 -> 1059556000
O29: Thomas Blake | P29: =SUMIFS('Cleaned Data'!$G$5:$G$226,'Cleaned Data'!$D$5:$D$226,O29) -> 1435564500 | Q29: =COUNTIFS('Cleaned Data'!$D$5:$D$226,O29) -> 7 | R29: =P29+ROW()/10000000 -> 1435564500
A30: 4) TOP 10 DIRECTORS BY REVENUE | F30: 5) TOP 10 HIGHEST GROSSING MOVIES | O30: Tom Ashworth | P30: =SUMIFS('Cleaned Data'!$G$5:$G$226,'Cleaned Data'!$D$5:$D$226,O30) -> 1839293000 | Q30: =COUNTIFS('Cleaned Data'!$D$5:$D$226,O30) -> 10 | R30: =P30+ROW()/10000000 -> 1839293000
A31: Rank | B31: Director | C31: Total Revenue | D31: Movie Count | F31: Rank | G31: Movie Title | H31: Genre | I31: Director | J31: Revenue | O31: Unknown | P31: =SUMIFS('Cleaned Data'!$G$5:$G$226,'Cleaned Data'!$D$5:$D$226,O31) -> 250728000 | Q31: =COUNTIFS('Cleaned Data'!$D$5:$D$226,O31) -> 4 | R31: =P31+ROW()/10000000 -> 2.50728e+08
A32: 1 | B32: =INDEX($O$3:$O$33,MATCH(LARGE($R$3:$R$33,1),$R$3:$R$33,0)) -> Isabella Rossi | C32: =INDEX($P$3:$P$33,MATCH(LARGE($R$3:$R$33,1),$R$3:$R$33,0)) -> 2976056000 | D32: =INDEX($Q$3:$Q$33,MATCH(LARGE($R$3:$R$33,1),$R$3:$R$33,0)) -> 12 | F32: 1 | G32: =INDEX('Cleaned Data'!$B$5:$B$226,MATCH(LARGE('Cleaned Data'!$O$5:$O$226,1),'Cleaned Data'!$O$5:$O$226,0)) -> Lost Requiem | H32: =INDEX('Cleaned Data'!$C$5:$C$226,MATCH(LARGE('Cleaned Data'!$O$5:$O$226,1),'Cleaned Data'!$O$5:$O$226,0)) -> Fantasy | I32: =INDEX('Cleaned Data'!$D$5:$D$226,MATCH(LARGE('Cleaned Data'!$O$5:$O$226,1),'Cleaned Data'!$O$5:$O$226,0)) -> Isabella Rossi | J32: =INDEX('Cleaned Data'!$G$5:$G$226,MATCH(LARGE('Cleaned Data'!$O$5:$O$226,1),'Cleaned Data'!$O$5:$O$226,0)) -> 1456529000 | O32: Victor Alvarez | P32: =SUMIFS('Cleaned Data'!$G$5:$G$226,'Cleaned Data'!$D$5:$D$226,O32) -> 845946500 | Q32: =COUNTIFS('Cleaned Data'!$D$5:$D$226,O32) -> 10 | R32: =P32+ROW()/10000000 -> 8.459465e+08
A33: 2 | B33: =INDEX($O$3:$O$33,MATCH(LARGE($R$3:$R$33,2),$R$3:$R$33,0)) -> Grace Kim | C33: =INDEX($P$3:$P$33,MATCH(LARGE($R$3:$R$33,2),$R$3:$R$33,0)) -> 2720814000 | D33: =INDEX($Q$3:$Q$33,MATCH(LARGE($R$3:$R$33,2),$R$3:$R$33,0)) -> 7 | F33: 2 | G33: =INDEX('Cleaned Data'!$B$5:$B$226,MATCH(LARGE('Cleaned Data'!$O$5:$O$226,2),'Cleaned Data'!$O$5:$O$226,0)) -> Silver Horizon | H33: =INDEX('Cleaned Data'!$C$5:$C$226,MATCH(LARGE('Cleaned Data'!$O$5:$O$226,2),'Cleaned Data'!$O$5:$O$226,0)) -> Sci-Fi | I33: =INDEX('Cleaned Data'!$D$5:$D$226,MATCH(LARGE('Cleaned Data'!$O$5:$O$226,2),'Cleaned Data'!$O$5:$O$226,0)) -> Amara Johnson | J33: =INDEX('Cleaned Data'!$G$5:$G$226,MATCH(LARGE('Cleaned Data'!$O$5:$O$226,2),'Cleaned Data'!$O$5:$O$226,0)) -> 1407192000 | O33: Yuki Sato | P33: =SUMIFS('Cleaned Data'!$G$5:$G$226,'Cleaned Data'!$D$5:$D$226,O33) -> 659051000 | Q33: =COUNTIFS('Cleaned Data'!$D$5:$D$226,O33) -> 5 | R33: =P33+ROW()/10000000 -> 6.59051e+08
A34: 3 | B34: =INDEX($O$3:$O$33,MATCH(LARGE($R$3:$R$33,3),$R$3:$R$33,0)) -> Olivia Bennett | C34: =INDEX($P$3:$P$33,MATCH(LARGE($R$3:$R$33,3),$R$3:$R$33,0)) -> 2547597000 | D34: =INDEX($Q$3:$Q$33,MATCH(LARGE($R$3:$R$33,3),$R$3:$R$33,0)) -> 14 | F34: 3 | G34: =INDEX('Cleaned Data'!$B$5:$B$226,MATCH(LARGE('Cleaned Data'!$O$5:$O$226,3),'Cleaned Data'!$O$5:$O$226,0)) -> Sacred Reckoning | H34: =INDEX('Cleaned Data'!$C$5:$C$226,MATCH(LARGE('Cleaned Data'!$O$5:$O$226,3),'Cleaned Data'!$O$5:$O$226,0)) -> Action | I34: =INDEX('Cleaned Data'!$D$5:$D$226,MATCH(LARGE('Cleaned Data'!$O$5:$O$226,3),'Cleaned Data'!$O$5:$O$226,0)) -> Olivia Bennett | J34: =INDEX('Cleaned Data'!$G$5:$G$226,MATCH(LARGE('Cleaned Data'!$O$5:$O$226,3),'Cleaned Data'!$O$5:$O$226,0)) -> 1271415000
A35: 4 | B35: =INDEX($O$3:$O$33,MATCH(LARGE($R$3:$R$33,4),$R$3:$R$33,0)) -> Amara Johnson | C35: =INDEX($P$3:$P$33,MATCH(LARGE($R$3:$R$33,4),$R$3:$R$33,0)) -> 2062082000 | D35: =INDEX($Q$3:$Q$33,MATCH(LARGE($R$3:$R$33,4),$R$3:$R$33,0)) -> 7 | F35: 4 | G35: =INDEX('Cleaned Data'!$B$5:$B$226,MATCH(LARGE('Cleaned Data'!$O$5:$O$226,4),'Cleaned Data'!$O$5:$O$226,0)) -> Silent Reckoning | H35: =INDEX('Cleaned Data'!$C$5:$C$226,MATCH(LARGE('Cleaned Data'!$O$5:$O$226,4),'Cleaned Data'!$O$5:$O$226,0)) -> Fantasy | I35: =INDEX('Cleaned Data'!$D$5:$D$226,MATCH(LARGE('Cleaned Data'!$O$5:$O$226,4),'Cleaned Data'!$O$5:$O$226,0)) -> Grace Kim | J35: =INDEX('Cleaned Data'!$G$5:$G$226,MATCH(LARGE('Cleaned Data'!$O$5:$O$226,4),'Cleaned Data'!$O$5:$O$226,0)) -> 1205730000
A36: 5 | B36: =INDEX($O$3:$O$33,MATCH(LARGE($R$3:$R$33,5),$R$3:$R$33,0)) -> Clara Dubois | C36: =INDEX($P$3:$P$33,MATCH(LARGE($R$3:$R$33,5),$R$3:$R$33,0)) -> 1941688000 | D36: =INDEX($Q$3:$Q$33,MATCH(LARGE($R$3:$R$33,5),$R$3:$R$33,0)) -> 12 | F36: 5 | G36: =INDEX('Cleaned Data'!$B$5:$B$226,MATCH(LARGE('Cleaned Data'!$O$5:$O$226,5),'Cleaned Data'!$O$5:$O$226,0)) -> Burning Paradox | H36: =INDEX('Cleaned Data'!$C$5:$C$226,MATCH(LARGE('Cleaned Data'!$O$5:$O$226,5),'Cleaned Data'!$O$5:$O$226,0)) -> Action | I36: =INDEX('Cleaned Data'!$D$5:$D$226,MATCH(LARGE('Cleaned Data'!$O$5:$O$226,5),'Cleaned Data'!$O$5:$O$226,0)) -> Elena Voss | J36: =INDEX('Cleaned Data'!$G$5:$G$226,MATCH(LARGE('Cleaned Data'!$O$5:$O$226,5),'Cleaned Data'!$O$5:$O$226,0)) -> 959689000
A37: 6 | B37: =INDEX($O$3:$O$33,MATCH(LARGE($R$3:$R$33,6),$R$3:$R$33,0)) -> Tom Ashworth | C37: =INDEX($P$3:$P$33,MATCH(LARGE($R$3:$R$33,6),$R$3:$R$33,0)) -> 1839293000 | D37: =INDEX($Q$3:$Q$33,MATCH(LARGE($R$3:$R$33,6),$R$3:$R$33,0)) -> 10 | F37: 6 | G37: =INDEX('Cleaned Data'!$B$5:$B$226,MATCH(LARGE('Cleaned Data'!$O$5:$O$226,6),'Cleaned Data'!$O$5:$O$226,0)) -> Distant Legacy | H37: =INDEX('Cleaned Data'!$C$5:$C$226,MATCH(LARGE('Cleaned Data'!$O$5:$O$226,6),'Cleaned Data'!$O$5:$O$226,0)) -> Animation | I37: =INDEX('Cleaned Data'!$D$5:$D$226,MATCH(LARGE('Cleaned Data'!$O$5:$O$226,6),'Cleaned Data'!$O$5:$O$226,0)) -> Marcus Reyes | J37: =INDEX('Cleaned Data'!$G$5:$G$226,MATCH(LARGE('Cleaned Data'!$O$5:$O$226,6),'Cleaned Data'!$O$5:$O$226,0)) -> 938683000
A38: 7 | B38: =INDEX($O$3:$O$33,MATCH(LARGE($R$3:$R$33,7),$R$3:$R$33,0)) -> Marcus Reyes | C38: =INDEX($P$3:$P$33,MATCH(LARGE($R$3:$R$33,7),$R$3:$R$33,0)) -> 1590974000 | D38: =INDEX($Q$3:$Q$33,MATCH(LARGE($R$3:$R$33,7),$R$3:$R$33,0)) -> 7 | F38: 7 | G38: =INDEX('Cleaned Data'!$B$5:$B$226,MATCH(LARGE('Cleaned Data'!$O$5:$O$226,7),'Cleaned Data'!$O$5:$O$226,0)) -> Shadow Legacy | H38: =INDEX('Cleaned Data'!$C$5:$C$226,MATCH(LARGE('Cleaned Data'!$O$5:$O$226,7),'Cleaned Data'!$O$5:$O$226,0)) -> Fantasy | I38: =INDEX('Cleaned Data'!$D$5:$D$226,MATCH(LARGE('Cleaned Data'!$O$5:$O$226,7),'Cleaned Data'!$O$5:$O$226,0)) -> Tom Ashworth | J38: =INDEX('Cleaned Data'!$G$5:$G$226,MATCH(LARGE('Cleaned Data'!$O$5:$O$226,7),'Cleaned Data'!$O$5:$O$226,0)) -> 800043000
A39: 8 | B39: =INDEX($O$3:$O$33,MATCH(LARGE($R$3:$R$33,8),$R$3:$R$33,0)) -> Ingrid Solberg | C39: =INDEX($P$3:$P$33,MATCH(LARGE($R$3:$R$33,8),$R$3:$R$33,0)) -> 1563723000 | D39: =INDEX($Q$3:$Q$33,MATCH(LARGE($R$3:$R$33,8),$R$3:$R$33,0)) -> 12 | F39: 8 | G39: =INDEX('Cleaned Data'!$B$5:$B$226,MATCH(LARGE('Cleaned Data'!$O$5:$O$226,8),'Cleaned Data'!$O$5:$O$226,0)) -> Eternal Echoes Rising | H39: =INDEX('Cleaned Data'!$C$5:$C$226,MATCH(LARGE('Cleaned Data'!$O$5:$O$226,8),'Cleaned Data'!$O$5:$O$226,0)) -> Adventure | I39: =INDEX('Cleaned Data'!$D$5:$D$226,MATCH(LARGE('Cleaned Data'!$O$5:$O$226,8),'Cleaned Data'!$O$5:$O$226,0)) -> Ingrid Solberg | J39: =INDEX('Cleaned Data'!$G$5:$G$226,MATCH(LARGE('Cleaned Data'!$O$5:$O$226,8),'Cleaned Data'!$O$5:$O$226,0)) -> 685629000
A40: 9 | B40: =INDEX($O$3:$O$33,MATCH(LARGE($R$3:$R$33,9),$R$3:$R$33,0)) -> James Whitfield | C40: =INDEX($P$3:$P$33,MATCH(LARGE($R$3:$R$33,9),$R$3:$R$33,0)) -> 1514682000 | D40: =INDEX($Q$3:$Q$33,MATCH(LARGE($R$3:$R$33,9),$R$3:$R$33,0)) -> 11 | F40: 9 | G40: =INDEX('Cleaned Data'!$B$5:$B$226,MATCH(LARGE('Cleaned Data'!$O$5:$O$226,9),'Cleaned Data'!$O$5:$O$226,0)) -> Midnight Echoes | H40: =INDEX('Cleaned Data'!$C$5:$C$226,MATCH(LARGE('Cleaned Data'!$O$5:$O$226,9),'Cleaned Data'!$O$5:$O$226,0)) -> Horror | I40: =INDEX('Cleaned Data'!$D$5:$D$226,MATCH(LARGE('Cleaned Data'!$O$5:$O$226,9),'Cleaned Data'!$O$5:$O$226,0)) -> Grace Kim | J40: =INDEX('Cleaned Data'!$G$5:$G$226,MATCH(LARGE('Cleaned Data'!$O$5:$O$226,9),'Cleaned Data'!$O$5:$O$226,0)) -> 660031000
...

Sheet Cleaned Data
A1: CLEANED DATA
A2: 222 records | Deduplicated, missing values imputed, formatting standardized | Profit & ROI %% derived.
A4: Movie ID | B4: Movie Title | C4: Genre | D4: Director | E4: Release Year | F4: Budget | G4: Revenue | H4: IMDb Rating | I4: Runtime | J4: Language | K4: Production Company | L4: Country | M4: Profit | N4: ROI % | O4: RankKey
A5: 1 | B5: Crimson Horizon | C5: Sci-Fi | D5: Peter Novak | E5: 2000 | F5: 103880000 | G5: 387550000 | H5: 5.6 | I5: 153 | J5: Portuguese | K5: Horizon Media Group | L5: France | M5: 283670000 | N5: 273.1 | O5: =G5+ROW()/10000000 -> 3.8755e+08
A6: 2 | B6: Endless Empire | C6: Horror | D6: Clara Dubois | E6: 2000 | F6: 26788000 | G6: 67535000 | H6: 5.7 | I6: 116 | J6: Italian | K6: Northgate Pictures | L6: India | M6: 40747000 | N6: 152.1 | O6: =G6+ROW()/10000000 -> 67535000
A7: 3 | B7: Fractured Kingdom | C7: Adventure | D7: Elena Voss | E7: 2000 | F7: 1000000 | G7: 5281000 | H7: 7.9 | I7: 116 | J7: Japanese | K7: Horizon Media Group | L7: South Korea | M7: 4281000 | N7: 428.1 | O7: =G7+ROW()/10000000 -> 5281000
A8: 4 | B8: Fractured River | C8: Documentary | D8: Ben Okafor | E8: 2000 | F8: 6927000 | G8: 22745000 | H8: 7.4 | I8: 149 | J8: Italian | K8: Echo Ridge Productions | L8: South Korea | M8: 15818000 | N8: 228.4 | O8: =G8+ROW()/10000000 -> 22745000
A9: 5 | B9: Golden Paradox | C9: Sci-Fi | D9: Thomas Blake | E9: 2000 | F9: 170618000 | G9: 557195000 | H9: 5.1 | I9: 130 | J9: English | K9: Redwood Entertainment | L9: Japan | M9: 386577000 | N9: 226.6 | O9: =G9+ROW()/10000000 -> 5.57195e+08
A10: 6 | B10: Last Reckoning | C10: Sci-Fi | D10: Unknown | E10: 2000 | F10: 108788500 | G10: 57272000 | H10: 7.1 | I10: 122 | J10: Japanese | K10: Ironvale Studios | L10: India | M10: -51516500 | N10: -47.4 | O10: =G10+ROW()/10000000 -> 57272000
A11: 7 | B11: Last Reckoning | C11: Sci-Fi | D11: Isabella Rossi | E11: 2000 | F11: 44893000 | G11: 57272000 | H11: 7.1 | I11: 122 | J11: Japanese | K11: Ironvale Studios | L11: India | M11: 12379000 | N11: 27.6 | O11: =G11+ROW()/10000000 -> 57272000
A12: 8 | B12: Midnight Kingdom Reborn | C12: Horror | D12: Elena Voss | E12: 2000 | F12: 15078000 | G12: 102587000 | H12: 6.2 | I12: 166 | J12: German | K12: BluePeak Films | L12: Spain | M12: 87509000 | N12: 580.4 | O12: =G12+ROW()/10000000 -> 1.02587e+08
A13: 9 | B13: Sacred Harbor | C13: Fantasy | D13: Connor Walsh | E13: 2000 | F13: 116909000 | G13: 357549000 | H13: 9.5 | I13: 134 | J13: Korean | K13: Crescent Bay Productions | L13: Australia | M13: 240640000 | N13: 205.8 | O13: =G13+ROW()/10000000 -> 3.57549e+08
A14: 10 | B14: Sacred Whisper | C14: Adventure | D14: Karim Haddad | E14: 2000 | F14: 94554000 | G14: 150397000 | H14: 6.3 | I14: 102 | J14: Portuguese | K14: Redwood Entertainment | L14: India | M14: 55843000 | N14: 59.1 | O14: =G14+ROW()/10000000 -> 1.50397e+08
A15: 11 | B15: Broken Whisper | C15: Sci-Fi | D15: Connor Walsh | E15: 2001 | F15: 192586000 | G15: 128183000 | H15: 7.3 | I15: 79 | J15: Hindi | K15: Pinnacle Films | L15: USA | M15: -64403000 | N15: -33.4 | O15: =G15+ROW()/10000000 -> 1.28183e+08
A16: 12 | B16: Golden Horizon Ii | C16: Sci-Fi | D16: David Chen | E16: 2001 | F16: 43385000 | G16: 79493000 | H16: 6.1 | I16: 95 | J16: German | K16: Pinnacle Films | L16: UK | M16: 36108000 | N16: 83.2 | O16: =G16+ROW()/10000000 -> 79493000
... A226: 222 | B226: Midnight Garden | C226: Romance | D226: Peter Novak | E226: 2024 | F226: 25908000 | G226: 71844000 | H226: 6.4 | I226: 105 | J226: English | K226: Meridian Studios | L226: Japan | M226: 45936000 | N226: 177.3 | O226: =G226+ROW()/10000000 -> 71844000

Sheet Raw Data
A1: RAW DATA (BEFORE CLEANING)
A2: Unprocessed export — contains duplicates, missing values and inconsistent formatting (kept intentionally for comparison).
A4: Movie Title | B4: Genre | C4: Director | D4: Release Year | E4: Budget | F4: Revenue | G4: IMDb Rating | H4: Runtime | I4: Language | J4: Production Company | K4: Country
A5: Shadow Whisper | B5: Adventure | C5: Sara Lindqvist | D5: 2021 | E5: 82753000.0 | F5: 87195000.0 | G5: 5.8 | H5: 112 | I5: English | J5: Vantage Point Pictures | K5: Brazil
A6: Broken Odyssey | B6: Documentary | C6: Tom Ashworth | D6: 2013 | E6: 4684000.0 | F6: 8545000.0 | G6: 5.4 | H6: 78 | I6: English | J6: Nova Cinema Works | K6: South Korea
A7: Broken Vault | B7: Romance | C7: Clara Dubois | D7: 2013 | E7: 13422000.0 | G7: 6.8 | H7: 101 | I7: German | J7: Pinnacle Films | K7: UK
A8: Silent Vault | B8: Documentary | C8: Isabella Rossi | D8: 2003 | E8: 3349000.0 | F8: 6578000.0 | G8: 7 | H8: 100 | I8: Korean | J8: Nova Cinema Works | K8: Canada
A9: Forgotten Vault | B9: Action | C9: Tom Ashworth | D9: 2005 | E9: 98711000.0 | F9: 63618000.0 | G9: 4.6 | H9: 100 | I9: Hindi | J9: Crescent Bay Productions | K9: Germany
A10: Forgotten Kingdom | B10: Fantasy | C10: Thomas Blake | D10: 2009 | E10: 90933000.0 | F10: 108359000.0 | G10: 5.9 | H10: 88 | I10: Mandarin | J10: Redwood Entertainment | K10: Australia
A11: Wild Echoes II | B11: Drama | C11: Sophie Laurent | D11: 2003 | E11: 25557000.0 | F11: 135214000.0 | G11: 4.6 | H11: 142 | I11: German | J11: BluePeak Films | K11: Spain
A12: Crimson Harbor | B12: Drama | C12: Hiroshi Tanaka | D12: 2018 | E12: 10215000.0 | F12: $15,179,000 | G12: 6 | H12: 133 | I12: German | J12: Golden Frame Studios | K12: Japan
A13: Silver Symphony Rising | B13: Adventure | C13: Clara Dubois | D13: 2002 | E13: 67401000.0 | F13: 193895000.0 | G13: 6.5 | H13: 135 | I13: Italian | J13: BluePeak Films | K13: Canada
A14: Silent Storm | B14: Romance | C14: Ryan Sullivan | D14: 2017 | E14: 18212000.0 | F14: 73840000.0 | G14: 7 | H14: 110 | I14: French | J14: BluePeak Films | K14: India
A15: Endless Horizon | B15: Crime | C15: Victor Alvarez | D15: 2022 | E15: 28427000.0 | F15: 102222000.0 | G15: 6 | H15: 102 | I15: Italian | J15: Horizon Media Group | K15: India
A16: Rising Garden | B16: Romance | C16: Victor Alvarez | D16: 2022 | E16: 27409000.0 | G16: 5 | H16: 123 | I16: Mandarin | J16: Silver Arc Studios | K16: Italy
A17: Midnight Vault III | B17: Animation | C17: Ben Okafor | D17: 2020 | F17: 123669000.0 | G17: 4.6 | H17: 110 | I17: Mandarin | J17: BluePeak Films | K17: South Korea
A18: Broken Paradox | B18: Documentary | C18: Sophie Laurent | D18: 2010 | E18: 3569000.0 | G18: 5.7 | H18: 116 | I18: Hindi | J18: Crescent Bay Productions | K18: Australia
A19: Endless Reckoning II | B19: Sci-Fi | C19: Tom Ashworth | D19: 2020 | E19: 162020000.0 | F19: 198120000.0 | G19: 7.6 | H19: 107 | I19: German | J19: Lumen Pictures | K19: Germany
A20: Crimson Symphony | B20: Sci-Fi | C20: James Whitfield | D20: 2010 | E20: 121884000.0 | F20: 260222000.0 | G20: 6.3 | H20: 133 | I20: German | J20: Echo Ridge Productions | K20: Spain
A21: Silver Reckoning | B21: Sci-Fi | C21: Ben Okafor | D21: 2011 | E21: 60571000.0 | F21: 212013000.0 | G21: 5.9 | H21: 96 | I21: Portuguese | J21: Redwood Entertainment | K21: Spain
A22: Broken Empire | B22: Romance | C22: Marcus Reyes | D22: 2018 | E22: 22369000.0 | F22: 66050000.0 | G22: 6.5 | H22: 107 | I22: Italian | J22: Nova Cinema Works | K22: Japan
A23: Wild Symphony | B23: Fantasy | C23: Mei Lin | D23: 2009 | E23: 63091000.0 | F23: 102002000.0 | G23: 4.2 | H23: 101 | I23: Spanish | J23: Crescent Bay Productions | K23: Japan
A24: Frozen Symphony | B24: Thriller | C24: Connor Walsh | D24: 2002 | E24: 53207000.0 | F24: 231283000.0 | G24: 7.9 | H24: 112 | I24: Mandarin | J24: Vantage Point Pictures
A25: Silver River | B25: Animation | C25: Isabella Rossi | D25: 2008 | E25: 108787000.0 | F25: 331790000.0 | G25: 7.4 | H25: 124 | I25: Hindi | J25: Silver Arc Studios | K25: China
A26: Endless River | B26: Sci-Fi | C26: Tom Ashworth | D26: 2016 | E26: 81997000.0 | F26: 311900000.0 | G26: 5.3 | H26: 109 | I26: Hindi | J26: Echo Ridge Productions | K26: China
A27: Rising Vault | B27: Action | C27: Thomas Blake | D27: 2005 | E27: $90,501,000 | F27: 218870000.0 | G27: 6.7 | I27: Portuguese | J27: Golden Frame Studios
A28: Sacred Kingdom | B28: Animation | C28: Karim Haddad | D28: 2012 | E28: 133989000.0 | F28: 610881000.0 | G28: 6.5 | I28: Hindi | J28: Cobalt Sky Films | K28: Canada
A29: Silver Voyage | B29: Adventure | C29: Sophie Laurent | D29: 2006 | E29: 66988000.0 | F29: 235993000.0 | G29: 6.6 | H29: 131 | I29: Italian | J29: Vantage Point Pictures | K29: Spain
A30: Wild Storm | B30: Animation | C30: Grace Kim | D30: 2010 | E30: 75907000.0 | F30: $95,643,000 | G30: 4.7 | H30: 116 | I30: Italian | J30: Pinnacle Films | K30: Spain
A31: Crimson Horizon | B31: Sci-Fi | C31: Peter Novak | D31: 2000 | E31: 103880000.0 | F31: 387550000.0 | G31: 5.6 | H31: 153 | I31: Portuguese | J31: Horizon Media Group | K31: France
A32: Wild Legacy | B32: Thriller | C32: Nadia Petrov | D32: 2002 | E32: 12590000.0 | F32: 79886000.0 | G32: 6.4 | H32: 136 | I32: Portuguese | J32: Golden Frame Studios | K32: Canada
A33: Lost Symphony | B33: Sci-Fi | C33: Peter Novak | D33: 2002 | E33: 134306000.0 | F33: 295352000.0 | G33: 6.5 | H33: 91 | I33: Korean | J33: Horizon Media Group | K33: China
A34: Burning Garden Reborn | B34: Action | C34: Victor Alvarez | D34: 2012 | E34: 88576000.0 | F34: 351044000.0 | G34: 6.5 | H34: 112 | I34: German | J34: Vantage Point Pictures | K34: South Korea
A35: Crimson Requiem | B35: Romance | C35: Yuki Sato | D35: 2009 | E35: 30046000.0 | F35: 39508000.0 | G35: 6.3 | H35: 103 | I35: Italian | J35: Meridian Studios | K35: India
A36: Forgotten Frontier | B36: Romance | C36: Hiroshi Tanaka | D36: 2021 | E36: 19892000.0 | F36: 23334000.0 | G36: 7.4 | H36: 87 | I36: Korean | J36: Echo Ridge Productions | K36: Australia
A37: Midnight Horizon | B37: Crime | C37: Tom Ashworth | D37: 2009 | E37: 31560000.0 | F37: 64134000.0 | G37: 3.5 | H37: 110 | I37: German | J37: Silver Arc Studios | K37: Germany
A38: Distant Paradox II | B38: Adventure | C38: Mei Lin | D38: 2016 | E38: 66473000.0 | F38: 216196000.0 | G38: 6.5 | H38: 134 | I38: Hindi | J38: Nova Cinema Works | K38: China
A39: Burning Voyage Reborn | B39: Animation | C39: Ben Okafor | D39: 2016 | E39: 89850000.0 | F39: 66754000.0 | G39: 5 | H39: 126 | I39: Portuguese | J39: Ironvale Studios | K39: France
A40: Broken Storm II | B40: Horror | C40: Nadia Petrov | D40: 2003 | E40: 22207000.0 | F40: 41049000.0 | G40: 4.3 | H40: 91 | I40: Spanish | J40: Echo Ridge Productions | K40: Japan
A41: Hidden Frontier | B41: Drama | C41: Hiroshi Tanaka | D41: 2004 | E41: 16676000.0 | F41: 57053000.0 | G41: 5.9 | H41: 124 | I41: Japanese | J41: Redwood Entertainment | K41: Spain
...

Sheet Read Me
B2: MOVIE BOX OFFICE ANALYTICS
B3: Interactive Excel Dashboard | Project Walkthrough & Interview Guide
B5: PROJECT OVERVIEW
B6: Goal | C6: Turn a raw, messy movie box-office dataset into a clean analytical model and an interactive, presentation-ready dashboard covering revenue, ratings, genres, directors and languages.
B7: Dataset | C7: 222 cleaned movie records (from 238 raw records) with Title, Genre, Director, Release Year, Budget, Revenue, IMDb Rating, Runtime, Language, Production Company and Country. This is an illustrative sample dataset built to mirror the shape of a real box-office dataset (e.g. Kaggle 'IMDb Movies' / 'TMDb' style data).
B9: WORKBOOK STRUCTURE
B10: Dashboard | C10: The main interactive view: KPI cards, 6 charts and a genre/year slicer-style filter panel.
B11: Pivot Tables | C11: Formula-driven summary tables (the 'pivot' calculation engine) that feed every chart on the Dashboard.
B12: Cleaned Data | C12: The clean dataset as a formatted native Excel Table, with conditional formatting and derived Profit / ROI columns.
B13: Raw Data | C13: The original, unprocessed data — duplicates, blanks and inconsistent formatting left intact so you can show the 'before'.
B15: DATA CLEANING STEPS PERFORMED
B16: 1. Duplicates | C16: 16 duplicate records removed (exact + case-insensitive Title+Year+Director matches).
B17: 2. Missing values | C17: Numeric fields (Budget, Revenue, IMDb Rating, Runtime) filled with the median for that movie's Genre. Text fields (Director, Language, Production Company, Country) filled with 'Unknown' rather than dropped, to preserve every row.
B18: 3. Formatting | C18: Trimmed stray whitespace, standardized text case (Title Case for names/genres), converted Budget/Revenue stored as '$123,000,000' text back into numbers, and normalized Release Year to a clean integer.
B19: 4. Derived fields | C19: Added Profit (Revenue - Budget) and ROI % ((Profit / Budget) x 100) to support financial analysis.
B21: HOW TO TALK ABOUT THIS IN AN INTERVIEW
B22: Data cleaning story | C22: "I started from a raw export with duplicates, missing fields and inconsistent formats. I deduplicated on a composite key, imputed numeric gaps using genre-level medians instead of the overall mean (to avoid skew from blockbusters), and standardized text formatting so grouping/pivoting would work reliably."
B23: Why genre-median imputation | C23: "A flat mean would understate horror-film budgets and overstate documentary budgets. Imputing within genre keeps the fill values realistic for that category."
B24: Why formulas, not hard-coded numbers | C24: "Every KPI and chart is driven by SUMIFS/COUNTIFS/AVERAGEIFS formulas against the Cleaned Data table, so the whole dashboard recalculates automatically if the underlying data changes — nothing is pasted as a static value."
B25: Interactivity | C25: "The Cleaned Data range is a native Excel Table, so it already supports one-click filtering. To add true clickable Slicers, select any cell in Cleaned Data, Insert > PivotTable, then Insert > Slicer on Genre / Release Year / Language — the sheet is structured so that takes under a minute."
B26: Design choices | C26: "I used a dark, cinema-inspired theme (navy background, gold accents echoing the IMDb rating star) so the dashboard reads like a studio analytics tool rather than a generic spreadsheet, and used conditional formatting (data bars, color scales) so patterns are visible without reading every number."
